<mujoco model="abb_gofa_crb15000_10_152">
  <compiler angle="radian" meshdir="assets/" texturedir="assets/"/>
  <asset>
    <mesh file="full/base_link/base_link.obj" scale="1.0 1.0 1.0"/>
    <material name="material_base_link_0" specular="0.20000000000000004" shininess="1.0" rgba="0.43921569 0.43921569 0.43921569 1.0"/>
    <mesh file="full/link_1/link_1.obj" scale="1.0 1.0 1.0"/>
    <material name="material_link_1_0" specular="0.20000000000000004" shininess="1.0" rgba="0.43921569 0.43921569 0.43921569 1.0"/>
    <mesh file="full/link_2/link_2_0.obj" scale="1.0 1.0 1.0"/>
    <mesh file="full/link_2/link_2_1.obj" scale="1.0 1.0 1.0"/>
    <material name="material_link_2_0" specular="0.20000000000000004" shininess="1.0" rgba="0.43921569 0.43921569 0.43921569 1.0"/>
    <material name="material_link_2_1" specular="0.20000000000000004" shininess="1.0" rgba="1.00000000 1.00000000 1.00000000 1.0"/>
    <mesh file="full/link_3/link_3.obj" scale="1.0 1.0 1.0"/>
    <material name="material_link_3_0" specular="0.20000000000000004" shininess="1.0" rgba="0.43921569 0.43921569 0.43921569 1.0"/>
    <mesh file="full/link_4/link_4_0.obj" scale="1.0 1.0 1.0"/>
    <mesh file="full/link_4/link_4_1.obj" scale="1.0 1.0 1.0"/>
    <mesh file="full/link_4/link_4_2.obj" scale="1.0 1.0 1.0"/>
    <material name="material_link_4_0" specular="0.20000000000000004" shininess="1.0" rgba="0.09803922 0.09803922 0.09803922 1.0"/>
    <material name="material_link_4_1" specular="0.20000000000000004" shininess="1.0" rgba="1.00000000 0.00000000 0.05490196 1.0"/>
    <material name="material_link_4_2" specular="0.20000000000000004" shininess="1.0" rgba="1.00000000 1.00000000 1.00000000 1.0"/>
    <mesh file="full/link_5/link_5_0.obj" scale="1.0 1.0 1.0"/>
    <mesh file="full/link_5/link_5_1.obj" scale="1.0 1.0 1.0"/>
    <mesh file="full/link_5/link_5_2.obj" scale="1.0 1.0 1.0"/>
    <material name="material_link_5_0" specular="0.20000000000000004" shininess="1.0" rgba="0.00000000 1.00000000 0.00000000 1.0"/>
    <material name="material_link_5_1" specular="0.20000000000000004" shininess="1.0" rgba="0.43921569 0.43921569 0.43921569 1.0"/>
    <material name="material_link_5_2" specular="0.20000000000000004" shininess="1.0" rgba="1.00000000 1.00000000 1.00000000 1.0"/>
    <mesh file="full/link_6/link_6.obj" scale="1.0 1.0 1.0"/>
    <material name="material_link_6_0" specular="0.20000000000000004" shininess="1.0" rgba="0.74509804 0.74509804 0.74509804 1.0"/>
  </asset>
  <worldbody>
    <body name="link_1" pos="0 0 0.218">
      <inertial pos="0.001 -0.001 -0.06" quat="0.925947 -0.377577 -0.00646255 -0.00402528" mass="11.8" diaginertia="0.110005 0.0900969 0.0898984"/>
      <joint name="joint_1" pos="0 0 0" axis="0 0 1" range="-4.71239 4.71239" actuatorfrcrange="-1000 1000" damping="5" frictionloss="1"/>
      <body name="link_2" pos="0.15 0 0.182">
        <inertial pos="-0.001 0 0.25" quat="0.999996 -0.00270263 -0.000249654 0.000149375" mass="17.5" diaginertia="0.49 0.460011 0.0899891"/>
        <joint name="joint_2" pos="0 0 0" axis="0 1 0" range="-3.14159 3.14159" actuatorfrcrange="-1000 1000" damping="5" frictionloss="1"/>
        <body name="link_3" pos="0 0 0.707">
          <inertial pos="0.1 0.001 0.032" quat="0.522377 0.476947 0.471574 0.526557" mass="7.5" diaginertia="0.090001 0.0805635 0.0244354"/>
          <joint name="joint_3" pos="0 0 0" axis="0 1 0" range="-3.92699 1.48353" actuatorfrcrange="-1000 1000" damping="5" frictionloss="1"/>
          <body name="link_4" pos="0 0 0.11">
            <inertial pos="0.38 0.001 0.005" quat="0.48246 0.507934 0.530637 0.477138" mass="2.7" diaginertia="0.0120024 0.011031 0.00596661"/>
            <joint name="joint_4" pos="0 0 0" axis="1 0 0" range="-3.14159 3.14159" actuatorfrcrange="-1000 1000" damping="5" frictionloss="1"/>
            <body name="link_5" pos="0.637 0 0">
              <inertial pos="0.011 -0.001 0" quat="0.495818 0.495818 0.504148 0.504148" mass="0.63" diaginertia="0.00110017 0.0009 0.000499833"/>
              <joint name="joint_5" pos="0 0 0" axis="0 1 0" range="-3.14159 3.14159" actuatorfrcrange="-1000 1000" damping="2" frictionloss="1"/>
              <body name="link_6" pos="0.101 0 0.08">
                <inertial pos="-0.007 0 0" mass="0.14" diaginertia="0.001 0.001 0.001"/>
                <joint name="joint_6" pos="0 0 0" axis="1 0 0" range="-4.71239 4.71239" actuatorfrcrange="-1000 1000" damping="1" frictionloss="1"/>
                <geom material="material_link_6_0" mesh="link_6" class="visual" pos="" quat=""/>
                <geom mesh="link_6" class="collision" pos="" quat=""/>
                <site name="link_6" pos="0 0 0" quat="1.0 0 0 0"/>
                <site name="flange" pos="0 0 0" quat="1.0 0 0 0"/>
                <site name="tool0" pos="0 0 0" quat="0.7071067811865476 0 0.7071067811865475 0"/>
              </body>
              <geom mesh="link_5_0" material="material_link_5_2" class="visual" pos="" quat=""/>
              <geom mesh="link_5_1" material="material_link_5_1" class="visual" pos="" quat=""/>
              <geom mesh="link_5_2" material="material_link_5_0" class="visual" pos="" quat=""/>
              <geom mesh="link_5_0" class="collision" pos="" quat=""/>
              <geom mesh="link_5_1" class="collision" pos="" quat=""/>
              <geom mesh="link_5_2" class="collision" pos="" quat=""/>
              <site name="link_5" pos="0 0 0" quat="1.0 0 0 0"/>
            </body>
            <geom mesh="link_4_0" material="material_link_4_2" class="visual" pos="" quat=""/>
            <geom mesh="link_4_1" material="material_link_4_1" class="visual" pos="" quat=""/>
            <geom mesh="link_4_2" material="material_link_4_0" class="visual" pos="" quat=""/>
            <geom mesh="link_4_0" class="collision" pos="" quat=""/>
            <geom mesh="link_4_1" class="collision" pos="" quat=""/>
            <geom mesh="link_4_2" class="collision" pos="" quat=""/>
            <site name="link_4" pos="0 0 0" quat="1.0 0 0 0"/>
          </body>
          <geom material="material_link_3_0" mesh="link_3" class="visual" pos="" quat=""/>
          <geom mesh="link_3" class="collision" pos="" quat=""/>
          <site name="link_3" pos="0 0 0" quat="1.0 0 0 0"/>
        </body>
        <geom mesh="link_2_0" material="material_link_2_1" class="visual" pos="" quat=""/>
        <geom mesh="link_2_1" material="material_link_2_0" class="visual" pos="" quat=""/>
        <geom mesh="link_2_0" class="collision" pos="" quat=""/>
        <geom mesh="link_2_1" class="collision" pos="" quat=""/>
        <site name="link_2" pos="0 0 0" quat="1.0 0 0 0"/>
      </body>
      <geom material="material_link_1_0" mesh="link_1" class="visual" pos="" quat=""/>
      <geom mesh="link_1" class="collision" pos="" quat=""/>
      <site name="link_1" pos="0 0 0" quat="1.0 0 0 0"/>
    </body>
    <geom material="material_base_link_0" mesh="base_link" class="visual" pos="" quat=""/>
    <geom mesh="base_link" class="collision" pos="" quat=""/>
    <site name="base_link" pos="0 0 0" quat="1.0 0 0 0"/>
    <site name="base" pos="0 0 0" quat="1.0 0 0 0"/>
  </worldbody>
</mujoco>