<?xml version="1.0" ?>
<!-- =================================================================================== -->
<!-- |    This document was autogenerated by xacro from /home/i/ros2_ws/src/abb_omnicore_ros2/robot_specific_config/abb_gofa_crb15000_10_152_moveit_config/config/gofa_crb15000_10_152.urdf.xacro | -->
<!-- |    EDITING THIS FILE BY HAND IS NOT RECOMMENDED                                 | -->
<!-- =================================================================================== -->
<robot name="abb_gofa_crb15000_10_152">
	<!-- Conversion were obtained from http://www.e-paint.co.uk/Lab_values.asp
       unless otherwise stated. -->
	<!-- link list -->
	<link name="base_link">
		<inertial>
			<mass value="13.5"/>
			<origin xyz="-0.025 0.000 0.110"/>
			<inertia ixx="0.10" ixy="0.0005" ixz="0.0003" iyy="0.14" iyz="-0.0002" izz="0.13"/>
		</inertial>
		<visual>
			<geometry>
				<mesh filename="full/base_link.obj"/>
			</geometry>
			<material name="">
				<color rgba="1 1 0 1"/>
			</material>
		</visual>
	</link>
	<link name="link_1">
		<inertial>
			<mass value="11.8"/>
			<origin xyz="0.001 -0.001 -0.060"/>
			<inertia ixx="0.11" ixy="-0.00005" ixz="0.0003" iyy="0.09" iyz="-0.0001" izz="0.09"/>
		</inertial>
		<visual>
			<geometry>
				<mesh filename="full/link_1.obj"/>
			</geometry>
			<material name="">
				<color rgba="1 1 0 1"/>
			</material>
		</visual>
	</link>
	<link name="link_2">
		<inertial>
			<mass value="17.5"/>
			<origin xyz="-0.001 0.000 0.250"/>
			<inertia ixx="0.49" ixy="0.00001" ixz="0.0002" iyy="0.46" iyz="-0.002" izz="0.09"/>
		</inertial>
		<visual>
			<geometry>
				<mesh filename="full/link_2.obj"/>
			</geometry>
			<material name="">
				<color rgba="1 1 0 1"/>
			</material>
		</visual>
	</link>
	<link name="link_3">
		<inertial>
			<mass value="7.5"/>
			<origin xyz="0.100 0.001 0.032"/>
			<inertia ixx="0.025" ixy="0.0001" ixz="-0.0056" iyy="0.09" iyz="0.0001" izz="0.08"/>
		</inertial>
		<visual>
			<geometry>
				<mesh filename="full/link_3.obj"/>
			</geometry>
			<material name="">
				<color rgba="1 1 0 1"/>
			</material>
		</visual>
	</link>
	<link name="link_4">
		<inertial>
			<mass value="2.7"/>
			<origin xyz="0.380 0.001 0.005"/>
			<inertia ixx="0.006" ixy="-0.0001" ixz="0.0004" iyy="0.012" iyz="-0.00002" izz="0.011"/>
		</inertial>
		<visual>
			<geometry>
				<mesh filename="full/link_4.obj"/>
			</geometry>
			<material name="">
				<color rgba="1 1 0 1"/>
			</material>
		</visual>
	</link>
	<link name="link_5">
		<inertial>
			<mass value="0.63"/>
			<origin xyz="0.011 -0.001 0.000"/>
			<inertia ixx="0.0005" ixy="-0.00001" ixz="0.0" iyy="0.0011" iyz="0.0" izz="0.0009"/>
		</inertial>
		<visual>
			<geometry>
				<mesh filename="full/link_5.obj"/>
			</geometry>
			<material name="">
				<color rgba="1 1 0 1"/>
			</material>
		</visual>
	</link>
	<link name="link_6">
		<inertial>
			<mass value="0.14"/>
			<origin rpy="0 0 0" xyz="-0.007 0.000 0.0"/>
			<inertia ixx="0.001" ixy="0" ixz="0" iyy="0.001" iyz="0" izz="0.001"/>
		</inertial>
		<visual>
			<geometry>
				<mesh filename="full/link_6.obj"/>
			</geometry>
			<material name="">
				<color rgba="1 1 0 1"/>
			</material>
		</visual>
	</link>
	<!-- end of link list -->
	<!-- joint list -->
	<!-- GoFa CRB15000-10/1.52 Joint Specifications -->
	<!-- xyz/rpy from Sunrise-Robotics abb_ros2 repository -->
	<!-- Axis 1: ±270°, 120°/s -->
	<joint name="joint_1" type="revolute">
		<origin rpy="0 0 0" xyz="0 0 0.218"/>
		<axis xyz="0 0 1"/>
		<parent link="base_link"/>
		<child link="link_1"/>
		<limit effort="1000" lower="-4.71238898038469" upper="4.71238898038469" velocity="2.0943951023931953"/>
		<dynamics damping="5.0" friction="1.0"/>
	</joint>
	<!-- Axis 2: ±180°, 120°/s -->
	<joint name="joint_2" type="revolute">
		<origin rpy="0 0 0" xyz="0.150 0 0.182"/>
		<axis xyz="0 1 0"/>
		<parent link="link_1"/>
		<child link="link_2"/>
		<limit effort="1000" lower="-3.141592653589793" upper="3.141592653589793" velocity="2.0943951023931953"/>
		<dynamics damping="5.0" friction="1.0"/>
	</joint>
	<!-- Axis 3: -225°/+85°, 125°/s -->
	<joint name="joint_3" type="revolute">
		<origin rpy="0 0 0" xyz="0 0 0.707"/>
		<axis xyz="0 1 0"/>
		<parent link="link_2"/>
		<child link="link_3"/>
		<limit effort="1000" lower="-3.9269908169872414" upper="1.4835298641951802" velocity="2.181661564992912"/>
		<dynamics damping="5.0" friction="1.0"/>
	</joint>
	<!-- Axis 4: ±180°, 200°/s -->
	<joint name="joint_4" type="revolute">
		<origin rpy="0 0 0" xyz="0 0 0.110"/>
		<axis xyz="1 0 0"/>
		<parent link="link_3"/>
		<child link="link_4"/>
		<limit effort="1000" lower="-3.141592653589793" upper="3.141592653589793" velocity="3.490658503988659"/>
		<dynamics damping="5.0" friction="1.0"/>
	</joint>
	<!-- Axis 5: ±180°, 200°/s -->
	<joint name="joint_5" type="revolute">
		<origin rpy="0 0 0" xyz="0.637 0 0"/>
		<axis xyz="0 1 0"/>
		<parent link="link_4"/>
		<child link="link_5"/>
		<limit effort="1000" lower="-3.141592653589793" upper="3.141592653589793" velocity="3.490658503988659"/>
		<dynamics damping="2.0" friction="1.0"/>
	</joint>
	<!-- Axis 6: ±270°, 200°/s -->
	<joint name="joint_6" type="revolute">
		<origin rpy="0 0 0" xyz="0.101 0 0.080"/>
		<axis xyz="1 0 0"/>
		<parent link="link_5"/>
		<child link="link_6"/>
		<limit effort="1000" lower="-4.71238898038469" upper="4.71238898038469" velocity="3.490658503988659"/>
		<dynamics damping="1.0" friction="1.0"/>
	</joint>
	<!-- end of joint list -->
	<!-- ROS-Industrial 'base' frame: base_link to ABB World Coordinates transform -->
	<link name="base"/>
	<joint name="base_link-base" type="fixed">
		<origin rpy="0 0 0" xyz="0 0 0"/>
		<parent link="base_link"/>
		<child link="base"/>
	</joint>
	<!-- ROS-Industrial 'flange' frame: attachment point for EEF models -->
	<link name="flange"/>
	<joint name="joint_6-flange" type="fixed">
		<origin rpy="0 0 0" xyz="0 0 0"/>
		<parent link="link_6"/>
		<child link="flange"/>
	</joint>
	<!-- ROS-Industrial 'tool0' frame: all-zeros tool frame -->
	<link name="tool0"/>
	<joint name="flange-tool0" type="fixed">
		<origin rpy="0 1.5707963267948966 0" xyz="0 0 0"/>
		<parent link="flange"/>
		<child link="tool0"/>
	</joint>
	<ros2_control name="ABBMultiInterfaceHardware" type="system">
		<hardware>
			<plugin>mock_components/GenericSystem</plugin>
			<param name="fake_sensor_commands">false</param>
			<param name="state_following_offset">0.0</param>
		</hardware>
		<joint name="joint_1">
			<command_interface name="position">
				<param name="min">-4.71238898038469</param>
				<param name="max">4.71238898038469</param>
			</command_interface>
			<command_interface name="velocity"/>
			<state_interface name="position">
				<param name="initial_value">0.0</param>
			</state_interface>
			<state_interface name="velocity"/>
		</joint>
		<joint name="joint_2">
			<command_interface name="position">
				<param name="min">-3.141592653589793</param>
				<param name="max">3.141592653589793</param>
			</command_interface>
			<command_interface name="velocity"/>
			<state_interface name="position">
				<param name="initial_value">0.0</param>
			</state_interface>
			<state_interface name="velocity"/>
		</joint>
		<joint name="joint_3">
			<command_interface name="position">
				<param name="min">-3.9269908169872414</param>
				<param name="max">1.4835298641951802</param>
			</command_interface>
			<command_interface name="velocity"/>
			<state_interface name="position">
				<param name="initial_value">0.0</param>
			</state_interface>
			<state_interface name="velocity"/>
		</joint>
		<joint name="joint_4">
			<command_interface name="position">
				<param name="min">-3.141592653589793</param>
				<param name="max">3.141592653589793</param>
			</command_interface>
			<command_interface name="velocity"/>
			<state_interface name="position">
				<param name="initial_value">0.0</param>
			</state_interface>
			<state_interface name="velocity"/>
		</joint>
		<joint name="joint_5">
			<command_interface name="position">
				<param name="min">-3.141592653589793</param>
				<param name="max">3.141592653589793</param>
			</command_interface>
			<command_interface name="velocity"/>
			<state_interface name="position">
				<param name="initial_value">0.0</param>
			</state_interface>
			<state_interface name="velocity"/>
		</joint>
		<joint name="joint_6">
			<command_interface name="position">
				<param name="min">-4.71238898038469</param>
				<param name="max">4.71238898038469</param>
			</command_interface>
			<command_interface name="velocity"/>
			<state_interface name="position">
				<param name="initial_value">0.0</param>
			</state_interface>
			<state_interface name="velocity"/>
		</joint>
	</ros2_control>
	<mujoco>
		<compiler assetdir="assets" balanceinertia="true" discardvisual="false" strippath="false"/>
	</mujoco>
</robot>